Workbook

Sheet Sheet1
A1: SL. NO. | B1: ITEM CODE | C1: PHOTO | D1: PRODUCT TITLE (Powertex site) | E1: CATEGORY | F1: SUB-CATEGORY | G1: MRP (INR) | H1: MRP (KWD) | I1: NET PRICE (INR) | J1: NET PRICE (KWD) | K1: SPECIFICATIONS | L1: MATCH STATUS / NOTE
A2: 1 | B2: PPT-ML-16-G | D2: ML-16-G MultiLine Laser | E2: Power Tools | F2: MultiLine Laser | G2: 8800 | H2: =G2*Notes!$B$2 -> 28.2832 | I2: 8800 | J2: =I2*Notes!$B$2 -> 28.2832 | K2: — | L2: Listed on site without "PPT-" prefix (as "ML-16-G")
A3: 2 | B3: PPT-CL-BDX-10 | D3: PPT-BDX-10-2 Brushless Drill | E3: Power Tools | F3: Brushless Drill | G3: 6500 | H3: =G3*Notes!$B$2 -> 20.891 | I3: 6500 | J3: =I3*Notes!$B$2 -> 20.891 | K3: — | L3: Site lists as "PPT-BDX-10-2" (no "CL-" segment)
A4: 3 | B4: PPT-CL-BIDX-13 | D4: PPT-BIDX-13-2 Brushless Impact Drill | E4: Power Tools | F4: Brushless Drill | G4: 6900 | H4: =G4*Notes!$B$2 -> 22.1766 | I4: 6900 | J4: =I4*Notes!$B$2 -> 22.1766 | K4: — | L4: Site lists as "PPT-BIDX-13-2" (no "CL-" segment)
A5: 4 | B5: PPT-CL-BAGX-115 | D5: — | E5: — | F5: — | G5: — | H5: — | I5: — | J5: — | K5: — | L5: NOT FOUND on website (you already have a photo for this item in column C)
A6: 5 | B6: PPT-CL-BIWX-400 | D6: PPT-BIWX-400-2 Brushless Impact Wrench | E6: Power Tools | F6: Brushless Impact Drill | G6: 8500 | H6: =G6*Notes!$B$2 -> 27.319 | I6: 8500 | J6: =I6*Notes!$B$2 -> 27.319 | K6: — | L6: Site lists as "PPT-BIWX-400-2" (no "CL-" segment)
A7: 6 | B7: PPT-CL-EW-500-40 | D7: PPT-CL-EW-500-40 | E7: Power Tools | F7: Cordless | G7: 14500 | H7: =G7*Notes!$B$2 -> 46.603 | I7: 14500 | J7: =I7*Notes!$B$2 -> 46.603 | K7: — | L7: Exact match
A8: 7 | B8: PPT-CL-EW-700-40 | D8: PPT-CL-EW-700-40 | E8: Power Tools | F8: Cordless | G8: 19200 | H8: =G8*Notes!$B$2 -> 61.7088 | I8: 19200 | J8: =I8*Notes!$B$2 -> 61.7088 | K8: — | L8: Exact match
A9: 8 | B9: PPT-CL-EW-1600-40 | D9: — | E9: — | F9: — | G9: — | H9: — | I9: — | J9: — | K9: — | L9: NOT FOUND (site only has 60L variant: PPT-CL-EW-1600-60L) (you already have a photo for this item in column C)
A10: 9 | B10: PPT-CL-ID-140 | D10: PPT-CL-ID-140 | E10: Power Tools | F10: Cordless | G10: 8200 | H10: =G10*Notes!$B$2 -> 26.3548 | I10: 8200 | J10: =I10*Notes!$B$2 -> 26.3548 | K10: Battery: 16V/2.0Ah; No Load Speed: 0-1000Rpm; Rated Impact: 4000IMP; Torque: 140N.M | L10: Exact match
A11: 10 | B11: PPT-CL-CD-10-BL | D11: PPT-CL-CD-10-BL | E11: Power Tools | F11: Cordless | G11: 5500 | H11: =G11*Notes!$B$2 -> 17.677 | I11: 5500 | J11: =I11*Notes!$B$2 -> 17.677 | K11: — | L11: Exact match
A12: 11 | B12: PPT-CL-CD-10-HQ-BL | D12: PPT-CL-CD-10-HQ | E12: Power Tools | F12: Cordless | G12: 6600 | H12: =G12*Notes!$B$2 -> 21.2124 | I12: 6600 | J12: =I12*Notes!$B$2 -> 21.2124 | K12: Voltage: 12V; Low Speed: 0-400; High Speed: 0-1600; Max Torque: 40Nm; Batter Capacity: 2000mAh; Type: Li-ion | L12: Site lists as "PPT-CL-CD-10-HQ" (no "BL" suffix)
A13: 12 | B13: PPT-CL-ED-13-BL | D13: PPT-CL-ED-13-BL | E13: Power Tools | F13: Cordless | G13: 9700 | H13: =G13*Notes!$B$2 -> 31.1758 | I13: 9700 | J13: =I13*Notes!$B$2 -> 31.1758 | K13: Battery: 20V/4.0Ah; No Load Speed: 0-2000Rpm; Chuck Capacity: 13mm; Torque: 60N.M | L13: Exact match
A14: 13 | B14: PPT-GID-13A | D14: — | E14: — | F14: — | G14: — | H14: — | I14: — | J14: — | K14: — | L14: NOT FOUND on website (you already have a photo for this item in column C)
B15: PPT-GID13B | D15: — | E15: — | F15: — | G15: — | H15: — | I15: — | J15: — | K15: — | L15: NOT FOUND on website (you already have a photo for this item in column C)
A16: 13 | B16: PPT-AG-100-C | D16: PPT-AG-100-C Angle Grinder | E16: Power Tools | F16: Angle Grinder | G16: 3050 | H16: =G16*Notes!$B$2 -> 9.8027 | I16: 3050 | J16: =I16*Notes!$B$2 -> 9.8027 | K16: Weight: 2.1 Kg; No Load Speed(RPM): 11000; Rated Power Input(W): 800; Max Wheel Dia(MM): 100; Hole Diameter of Wheel(MM): 16; PCS/CTN: 8 | L16: Exact match
A17: 14 | B17: PPT-AG-115-950 | D17: — | E17: — | F17: — | G17: — | H17: — | I17: — | J17: — | K17: — | L17: NOT FOUND (only "PPT-AG-115 Carbon Brush" spare part exists) (you already have a photo for this item in column C)
A18: 15 | B18: PPT-AG-115-G | D18: — | E18: — | F18: — | G18: — | H18: — | I18: — | J18: — | K18: — | L18: NOT FOUND (only "PPT-AG-115 Carbon Brush" spare part exists) (you already have a photo for this item in column C)
A19: 16 | B19: PPT-AG-230-G | D19: PPT-AG-230-G Angle Grinder | E19: Power Tools | F19: Angle Grinder | G19: 6000 | H19: =G19*Notes!$B$2 -> 19.284 | I19: 6000 | J19: =I19*Notes!$B$2 -> 19.284 | K19: — | L19: Exact match
A20: 17 | B20: PPT-DH-38-G | D20: PPT-DH-38-G Demolition Hammer | E20: Power Tools | F20: Demolition Hammer | G20: 8400 | H20: =G20*Notes!$B$2 -> 26.9976 | I20: 8400 | J20: =I20*Notes!$B$2 -> 26.9976 | K20: Rated Input Power (W): 1150; Impact Rate (BPM): 4000; Impact Joules(J): 20; PCS/CTN: 3 | L20: Exact match
A21: 18 | B21: PPT-DH-11-G | D21: PPT-DH-11-G Demolition Hammer | E21: Power Tools | F21: Demolition Hammer | G21: 21000 | H21: =G21*Notes!$B$2 -> 67.494 | I21: 21000 | J21: =I21*Notes!$B$2 -> 67.494 | K21: — | L21: Exact match
A22: 19 | B22: PPT-DH-65-G | D22: PPT-DH-65-G Demolition Hammer | E22: Power Tools | F22: Demolition Hammer | G22: 20500 | H22: =G22*Notes!$B$2 -> 65.887 | I22: 20500 | J22: =I22*Notes!$B$2 -> 65.887 | K22: — | L22: Exact match
A23: 20 | B23: PPT-CM-110-G | D23: PPT-CM-110-G Marble Cutter | E23: Power Tools | F23: Marble Cutter | G23: 5000 | H23: =G23*Notes!$B$2 -> 16.07 | I23: 5000 | J23: =I23*Notes!$B$2 -> 16.07 | K23: — | L23: Exact match
A24: 21 | B24: PPT-CM-180-G | D24: PPT-CM-180-G Circular Saw | E24: Power Tools | F24: Circular Saw | G24: 6400 | H24: =G24*Notes!$B$2 -> 20.5696 | I24: 6400 | J24: =I24*Notes!$B$2 -> 20.5696 | K24: — | L24: Exact match
A25: 22 | B25: PPT-MS-255-HG | D25: PPT-MS-255-HG Miter Saw | E25: Power Tools | F25: Miter Saw | G25: 29500 | H25: =G25*Notes!$B$2 -> 94.813 | I25: 29500 | J25: =I25*Notes!$B$2 -> 94.813 | K25: — | L25: Exact match
A26: 23 | B26: PPT-TS-216 | D26: PPT-TS-216 Table ChainSaw | E26: Power Tools | F26: Table Saw | G26: 31000 | H26: =G26*Notes!$B$2 -> 99.634 | I26: 31000 | J26: =I26*Notes!$B$2 -> 99.634 | K26: — | L26: Exact match
A27: 24 | B27: PPT-TSS-255 | D27: — | E27: — | F27: — | G27: — | H27: — | I27: — | J27: — | K27: — | L27: NOT FOUND on website (you already have a photo for this item in column C)
A28: 25 | B28: PPT-TM-6-650 | D28: PPT-TM-6 Trimmer | E28: Power Tools | F28: Trimmer | G28: 3500 | H28: =G28*Notes!$B$2 -> 11.249 | I28: 3500 | J28: =I28*Notes!$B$2 -> 11.249 | K28: — | L28: Site lists as "PPT-TM-6" (no "-650" suffix)
A29: 26 | B29: PPT-RM-8-H | D29: PPT-RM-8-X Router Machine | E29: Power Tools | F29: Router Machine | G29: 6500 | H29: =G29*Notes!$B$2 -> 20.891 | I29: 6500 | J29: =I29*Notes!$B$2 -> 20.891 | K29: — | L29: Site lists as "PPT-RM-8-X Router Machine" (no "-H" suffix)
A30: 27 | B30: PPT-WC-002 | D30: PPT-WC-002 Wall Chaser | E30: Power Tools | F30: Wall Chaser | G30: 18000 | H30: =G30*Notes!$B$2 -> 57.852 | I30: 18000 | J30: =I30*Notes!$B$2 -> 57.852 | K30: Weight: 4.4 Kg; Rated Power Input(W): 2500; No Load Speed(RPM): 6400; Grooving Depth(MM): 20-42; Grooving Width(MM): 4-45MM; Blade Dia(MM): 129 | L30: Exact match
A31: 28 | B31: PPT-OS-110 | D31: PPT-OS-110 Orbital Sander | E31: Power Tools | F31: Orbital Sander | G31: 3000 | H31: =G31*Notes!$B$2 -> 9.642 | I31: 3000 | J31: =I31*Notes!$B$2 -> 9.642 | K31: Weight: 1.3 Kg; Rated Power Input(W): 150; Orbits Frequency(RPM): 12000; Pad Size(MM): 100x110; PCS/CTN: 16 | L31: Exact match
A32: 29 | B32: PPT-OS-114 | D32: PPT-OS-114 Orbital Sander | E32: Power Tools | F32: Orbital Sander | G32: 6400 | H32: =G32*Notes!$B$2 -> 20.5696 | I32: 6400 | J32: =I32*Notes!$B$2 -> 20.5696 | K32: Weight: 2.9 Kg; Rated Power Input(W): 520; Orbits Frequency(RPM): 10000; Pad Size(MM): 114x234; PCS/CTN: 8 | L32: Exact match
A33: 30 | B33: PPT-SP-180-C | D33: — | E33: — | F33: — | G33: — | H33: — | I33: — | J33: — | K33: — | L33: NOT FOUND (only base "PPT-SP-180" exists, no "-C" variant) (you already have a photo for this item in column C)
A34: 31 | B34: PPT-SP-180 | D34: PPT-SP-180 Sander Polisher | E34: Power Tools | F34: Sander Polisher | G34: 8000 | H34: =G34*Notes!$B$2 -> 25.712 | I34: 8000 | J34: =I34*Notes!$B$2 -> 25.712 | K34: Weight: 3.6 Kg; Rated Power Input(W): 750; No Load Speed(RPM): 2500-3400; Wheel Size(MM): 180; PCS/CTN: 4 | L34: Exact match
A35: 32 | B35: PPT-GG-13000-EWD | D35: PPT-GG-13000-EWD-Generator | E35: Generator | F35: Generator | G35: 150000 | H35: =G35*Notes!$B$2 -> 482.1 | I35: 150000 | J35: =I35*Notes!$B$2 -> 482.1 | K35: — | L35: Exact match
A36: 33 | B36: PPT-VC-30-H | D36: PPT-VC-30L-New Vacuum Cleaner | E36: Power Tools | F36: Vacuum Cleaner | G36: 14200 | H36: =G36*Notes!$B$2 -> 45.6388 | I36: 14200 | J36: =I36*Notes!$B$2 -> 45.6388 | K36: — | L36: Exact match
A37: 34 | B37: PPT-VC-60-H | D37: PPT-VC-60L-New Vacuum Cleaner | E37: Power Tools | F37: Vacuum Cleaner | G37: 25500 | H37: =G37*Notes!$B$2 -> 81.957 | I37: 25500 | J37: =I37*Notes!$B$2 -> 81.957 | K37: — | L37: Exact match
A38: 35 | B38: PPT-CC-30 | D38: PPT-CC-30 Carpet Cleaner | E38: Power Tools | F38: Cordless | G38: 32000 | H38: =G38*Notes!$B$2 -> 102.848 | I38: 32000 | J38: =I38*Notes!$B$2 -> 102.848 | K38: — | L38: Exact match (Carpet Cleaner)
A39: 36 | B39: PPT-CO-355-G | D39: PPT-CO-355-G Cut off Machine | E39: Power Tools | F39: Cut Off Machine | G39: 15000 | H39: =G39*Notes!$B$2 -> 48.21 | I39: 15000 | J39: =I39*Notes!$B$2 -> 48.21 | K39: — | L39: Exact match
A40: 37 | B40: PPT-CW-300 | D40: PPT-CW-300 Car Washer | E40: Power Tools | F40: Car Washer | G40: 14800 | H40: =G40*Notes!$B$2 -> 47.5672 | I40: 14800 | J40: =I40*Notes!$B$2 -> 47.5672 | K40: Rated Input Power (W): 2650; Working Pressure: 2850; Flow: 880L/h; Bar: 180; PCS/CTN: 2 | L40: Exact match
...

Sheet Notes
A1: How this sheet was built
A2: INR -> KWD exchange rate used (edit this cell to update all KWD prices): | B2: 0.003214 | C2: (1 INR ≈ 0.003214 KWD — mid-market rate, XE.com / Wise.com, 20 Aug 2026. Rates fluctuate — update before finalizing Shopify prices.)
A5: Your original PHOTO column (C) and its images were left untouched — those are your existing product photos.
A7: Columns D onward were added from powertextools.com (Powertex Powertools) product catalog data, matched to your
A8: item codes by exact / close model-number lookup against the site's own product database.
A9: Total item codes in your list: 47
A10: Matched to a product on the site: 38
A11: Not found on the site under that code: 9 (highlighted yellow on Sheet1 — you already have a photo for these in column C, but price/specs could not be pulled from the site).
A13: MRP (KWD) / NET PRICE (KWD): calculated with a formula from the INR price x the exchange rate in cell B2 above —
A14: change B2 to today's rate and every price on Sheet1 recalculates automatically.
A16: MATCH STATUS / NOTE column explains any difference between your item code and the code as listed on the site
A17: (e.g. a missing "-H" suffix, or a variant not sold separately).
